<?xml version="1.0" encoding="utf-8"?>
<!-- This URDF was automatically created by SolidWorks to URDF Exporter! Originally created by Stephen Brawner (brawner@gmail.com) 
     Commit Version: 1.6.0-4-g7f85cfe  Build Version: 1.6.7995.38578
     For more information, please see http://wiki.ros.org/sw_urdf_exporter -->
<robot
  name="arm_urdf">
  <link
    name="base_link">
    <inertial>
      <origin
        xyz="-0.0036798240314266 0.0334930245621403 -0.067619806748485"
        rpy="0 0 0" />
      <mass
        value="0.822890475760512" />
      <inertia
        ixx="0.00265323982881183"
        ixy="7.59478635142583E-07"
        ixz="7.2543380674244E-05"
        iyy="0.00293479013798865"
        iyz="-1.98795921819183E-05"
        izz="0.000494767896699545" />
    </inertial>
    <visual>
      <origin
        xyz="0 0 0"
        rpy="0 0 0" />
      <geometry>
        <mesh
          filename="package://arm_urdf/meshes/base_link.STL" />
      </geometry>
      <material
        name="">
        <color
          rgba="0.752941176470588 0.752941176470588 0.752941176470588 1" />
      </material>
    </visual>
    <collision>
      <origin
        xyz="0 0 0"
        rpy="0 0 0" />
      <geometry>
        <mesh
          filename="package://arm_urdf/meshes/base_link.STL" />
      </geometry>
    </collision>
  </link>
  <link
    name="link_1">
    <inertial>
      <origin
        xyz="-0.000276081625093938 0.0152801621673459 0.088256138789042"
        rpy="0 0 0" />
      <mass
        value="1.3578353114689" />
      <inertia
        ixx="0.00333814029262389"
        ixy="-2.04850450079554E-07"
        ixz="-7.28667321534616E-06"
        iyy="0.00122042869124216"
        iyz="-0.000124129203998039"
        izz="0.00317720477234305" />
    </inertial>
    <visual>
      <origin
        xyz="0 0 0"
        rpy="0 0 0" />
      <geometry>
        <mesh
          filename="package://arm_urdf/meshes/link_1.STL" />
      </geometry>
      <material
        name="">
        <color
          rgba="0.752941176470588 0.752941176470588 0.752941176470588 1" />
      </material>
    </visual>
    <collision>
      <origin
        xyz="0 0 0"
        rpy="0 0 0" />
      <geometry>
        <mesh
          filename="package://arm_urdf/meshes/link_1.STL" />
      </geometry>
    </collision>
  </link>
  <joint
    name="joint_1"
    type="continuous">
    <origin
      xyz="-0.0055997 0.011176 0.07441"
      rpy="0 0 0.081977" />
    <parent
      link="base_link" />
    <child
      link="link_1" />
    <axis
      xyz="0 0 1" />
  </joint>
  <link
    name="bicep">
    <inertial>
      <origin
        xyz="0.0253997592920813 0.145469939084208 0.0113059977652922"
        rpy="0 0 0" />
      <mass
        value="0.938810977916726" />
      <inertia
        ixx="0.00521724116914255"
        ixy="4.93886221515835E-06"
        ixz="0.00030112344979231"
        iyy="0.000948664160304474"
        iyz="-1.10661506891825E-05"
        izz="0.00467508585971214" />
    </inertial>
    <visual>
      <origin
        xyz="0 0 0"
        rpy="0 0 0" />
      <geometry>
        <mesh
          filename="package://arm_urdf/meshes/bicep.STL" />
      </geometry>
      <material
        name="">
        <color
          rgba="0.752941176470588 0.752941176470588 0.752941176470588 1" />
      </material>
    </visual>
    <collision>
      <origin
        xyz="0 0 0"
        rpy="0 0 0" />
      <geometry>
        <mesh
          filename="package://arm_urdf/meshes/bicep.STL" />
      </geometry>
    </collision>
  </link>
  <joint
    name="joint_2"
    type="continuous">
    <origin
      xyz="0 0.075 0.11064"
      rpy="2.3785 -0.3113 0.28497" />
    <parent
      link="link_1" />
    <child
      link="bicep" />
    <axis
      xyz="0.91355 0 0.40674" />
  </joint>
  <link
    name="forearm">
    <inertial>
      <origin
        xyz="0.0260237924033239 -0.0200101568371641 0.0222583522473769"
        rpy="0 0 0" />
      <mass
        value="1.14228048353566" />
      <inertia
        ixx="0.00399684434866099"
        ixy="-0.000131808044696208"
        ixz="4.40042111421313E-08"
        iyy="0.00374650344608502"
        iyz="-6.63579070807178E-09"
        izz="0.000741372239539919" />
    </inertial>
    <visual>
      <origin
        xyz="0 0 0"
        rpy="0 0 0" />
      <geometry>
        <mesh
          filename="package://arm_urdf/meshes/forearm.STL" />
      </geometry>
      <material
        name="">
        <color
          rgba="0.752941176470588 0.752941176470588 0.752941176470588 1" />
      </material>
    </visual>
    <collision>
      <origin
        xyz="0 0 0"
        rpy="0 0 0" />
      <geometry>
        <mesh
          filename="package://arm_urdf/meshes/forearm.STL" />
      </geometry>
    </collision>
  </link>
  <joint
    name="joint_3"
    type="continuous">
    <origin
      xyz="0 0.36 0"
      rpy="-0.88914 0.75522 -2.866" />
    <parent
      link="bicep" />
    <child
      link="forearm" />
    <axis
      xyz="0.91886 -0.39458 0" />
  </joint>
  <link
    name="wrist">
    <inertial>
      <origin
        xyz="-0.0717440741453156 0.00183296197726708 -0.317341322429344"
        rpy="0 0 0" />
      <mass
        value="41927.007299493" />
      <inertia
        ixx="8.83747563657208"
        ixy="-0.000124540550785035"
        ixz="-0.00121061700020869"
        iyy="8.83278204569789"
        iyz="-0.0229515226735155"
        izz="7.89645396325965" />
    </inertial>
    <visual>
      <origin
        xyz="0 0 0"
        rpy="0 0 0" />
      <geometry>
        <mesh
          filename="package://arm_urdf/meshes/wrist.STL" />
      </geometry>
      <material
        name="">
        <color
          rgba="0.752941176470588 0.752941176470588 0.752941176470588 1" />
      </material>
    </visual>
    <collision>
      <origin
        xyz="0 0 0"
        rpy="0 0 0" />
      <geometry>
        <mesh
          filename="package://arm_urdf/meshes/wrist.STL" />
      </geometry>
    </collision>
  </link>
  <joint
    name="joint_4"
    type="continuous">
    <origin
      xyz="0.045943 -0.019729 0"
      rpy="0 0 0.057924" />
    <parent
      link="forearm" />
    <child
      link="wrist" />
    <axis
      xyz="0 0 1" />
  </joint>
  <link
    name="left_claw">
    <inertial>
      <origin
        xyz="0.0038360337692791 0.0426668418390397 0.0236079003771448"
        rpy="0 0 0" />
      <mass
        value="0.0552769421141955" />
      <inertia
        ixx="6.98533291541758E-05"
        ixy="-8.99068548512217E-06"
        ixz="2.88652997947518E-09"
        iyy="4.18428081733545E-06"
        iyz="3.19458959966543E-08"
        izz="7.38079334032916E-05" />
    </inertial>
    <visual>
      <origin
        xyz="0 0 0"
        rpy="0 0 0" />
      <geometry>
        <mesh
          filename="package://arm_urdf/meshes/left_claw.STL" />
      </geometry>
      <material
        name="">
        <color
          rgba="0.752941176470588 0.752941176470588 0.752941176470588 1" />
      </material>
    </visual>
    <collision>
      <origin
        xyz="0 0 0"
        rpy="0 0 0" />
      <geometry>
        <mesh
          filename="package://arm_urdf/meshes/left_claw.STL" />
      </geometry>
    </collision>
  </link>
  <joint
    name="left_claw_joint"
    type="continuous">
    <origin
      xyz="-0.044746 -0.023196 -0.40274"
      rpy="-1.5708 0.14167 1.5708" />
    <parent
      link="wrist" />
    <child
      link="left_claw" />
    <axis
      xyz="0 0 1" />
  </joint>
  <link
    name="right_claw">
    <inertial>
      <origin
        xyz="0.00383606672828818 0.0426668402066062 -0.0252123039358644"
        rpy="0 0 0" />
      <mass
        value="0.0552769060198365" />
      <inertia
        ixx="6.98535705290192E-05"
        ixy="-8.99076507967866E-06"
        ixz="2.88280354022659E-09"
        iyy="4.18375084335393E-06"
        iyz="3.19477309144085E-08"
        izz="7.38076449036395E-05" />
    </inertial>
    <visual>
      <origin
        xyz="0 0 0"
        rpy="0 0 0" />
      <geometry>
        <mesh
          filename="package://arm_urdf/meshes/right_claw.STL" />
      </geometry>
      <material
        name="">
        <color
          rgba="0.752941176470588 0.752941176470588 0.752941176470588 1" />
      </material>
    </visual>
    <collision>
      <origin
        xyz="0 0 0"
        rpy="0 0 0" />
      <geometry>
        <mesh
          filename="package://arm_urdf/meshes/right_claw.STL" />
      </geometry>
    </collision>
  </link>
  <joint
    name="right_claw_joint"
    type="continuous">
    <origin
      xyz="-0.043119 0.023194 -0.40373"
      rpy="-1.5708 -0.18063 -1.5708" />
    <parent
      link="wrist" />
    <child
      link="right_claw" />
    <axis
      xyz="0 0 1" />
  </joint>
</robot>